<?xml version="1.0"?>
<robot name="six_wheel_robot">

  <!-- Define materials -->
  <material name="blue">
    <color rgba="0 0 1 1"/>
  </material>
  <material name="black">
    <color rgba="0 0 0 1"/>
  </material>
  <link name="base_foot_print"/>
  <!-- Base Link of the Car -->
  <link name="base_link">
    <visual>
      <geometry>
        <box size="2.0 1.0 0.5"/>
      </geometry>
      <material name="blue"/>
    </visual>
      <inertial>
    <mass value="5.0"/>
    <inertia ixx="0.5" ixy="0.0" ixz="0.0" iyy="1.0" iyz="0.0" izz="1.5"/>
  </inertial>
  </link>

  <!-- Front Left Wheel -->
  <link name="front_left_wheel">
    <visual>
      <geometry>
        <cylinder radius="0.3" length="0.2"/>
      </geometry>
      <material name="black"/>
    </visual>
  </link>

  <!-- Front Right Wheel -->
  <link name="front_right_wheel">
    <visual>
      <geometry>
        <cylinder radius="0.3" length="0.2"/>
      </geometry>
      <material name="black"/>
    </visual>
  </link>

  <!-- Middle Left Wheel -->
  <link name="middle_left_wheel">
    <visual>
      <geometry>
        <cylinder radius="0.3" length="0.2"/>
      </geometry>
      <material name="black"/>
    </visual>
  </link>

  <!-- Middle Right Wheel -->
  <link name="middle_right_wheel">
    <visual>
      <geometry>
        <cylinder radius="0.3" length="0.2"/>
      </geometry>
      <material name="black"/>
    </visual>
  </link>

  <!-- Rear Left Wheel -->
  <link name="rear_left_wheel">
    <visual>
      <geometry>
        <cylinder radius="0.3" length="0.2"/>
      </geometry>
      <material name="black"/>
    </visual>
  </link>

  <!-- Rear Right Wheel -->
  <link name="rear_right_wheel">
    <visual>
      <geometry>
        <cylinder radius="0.3" length="0.2"/>
      </geometry>
      <material name="black"/>
    </visual>
  </link>

  <!-- Joints -->

  <!-- Front Left Wheel Joint -->
  <joint name="front_left_wheel_joint" type="continuous">
    <parent link="base_link"/>
    <child link="front_left_wheel"/>
    <origin xyz="-0.8 0.5 -0.4" rpy="1.5708 0 0"/>
  </joint>

  <!-- Front Right Wheel Joint -->
  <joint name="front_right_wheel_joint" type="continuous">
    <parent link="base_link"/>
    <child link="front_right_wheel"/>
    <origin xyz="-0.8 -0.5 -0.4" rpy="1.5708 0 0"/>
  </joint>

  <!-- Middle Left Wheel Joint -->
  <joint name="middle_left_wheel_joint" type="continuous">
    <parent link="base_link"/>
    <child link="middle_left_wheel"/>
    <origin xyz="0 0.5 -0.4" rpy="1.5708 0 0"/>
  </joint>

  <!-- Middle Right Wheel Joint -->
  <joint name="middle_right_wheel_joint" type="continuous">
    <parent link="base_link"/>
    <child link="middle_right_wheel"/>
    <origin xyz="0 -0.5 -0.4" rpy="1.5708 0 0"/>
  </joint>

  <!-- Rear Left Wheel Joint -->
  <joint name="rear_left_wheel_joint" type="continuous">
    <parent link="base_link"/>
    <child link="rear_left_wheel"/>
    <origin xyz="0.8 0.5 -0.4" rpy="1.5708 0 0"/>
  </joint>

  <!-- Rear Right Wheel Joint -->
  <joint name="rear_right_wheel_joint" type="continuous">
    <parent link="base_link"/>
    <child link="rear_right_wheel"/>
    <origin xyz="0.8 -0.5 -0.4" rpy="1.5708 0 0"/>
  </joint>


<gazebo>
  <plugin name="diff_drive_controller" filename="libgazebo_ros_diff_drive.so">
    <ros>
      <namespace>/</namespace>
    </ros>
    <alwaysOn>true</alwaysOn>
    <updateRate>50</updateRate>
    <left_joint>front_left_wheel_joint middle_left_wheel_joint rear_left_wheel_joint</left_joint>
    <right_joint>front_right_wheel_joint middle_right_wheel_joint rear_right_wheel_joint</right_joint>
    <wheel_separation>1.0</wheel_separation>
    <wheel_diameter>0.6</wheel_diameter>
    <robot_base_frame>base_link</robot_base_frame>
  </plugin>
</gazebo>

</robot>
